Workbook

Sheet 2026
E2: User experience | G2: Logiciels et Données | I2: Infrastructure & Sécurité | K2: Ticketing | O2: Remarques
C3: 2026 | E3: # Tickets hors SLA clôture | F3: # Tickets hors SLA prise en charge | G3: # Automatisations métiers | H3: # Améliorations dans Odoo | I3: # Echecs tests phishing | J3: # Maintenances production | K3: # Demandes IT | M3: # Demandes non résolues | O3: Informations | P3: Réaction
C4: Mois | D4: Semaine | E4: IT Team | G4: Digital Manager | I4: Digital Coordinator | K4: Hebdo | L4: YTD N | M4: Hebdo | N4: YTD N
C5: 1 | D5: 1 | K5: 0 | L5: 0 | M5: 0 | N5: 0
C6: 1 | D6: 2 | K6: 41 | L6: =K6+L5 -> 41 | M6: 16 | N6: =M6+N5 -> 16
C7: 1 | D7: 3 | K7: 33 | L7: =K7+L6 -> 74 | M7: 6 | N7: =M7+N6 -> 22
C8: 1 | D8: 4 | K8: 39 | L8: =K8+L7 -> 113 | M8: 12 | N8: =M8+N7 -> 34
C9: 1 | D9: 5 | K9: 39 | L9: =K9+L8 -> 152 | M9: 20 | N9: =M9+N8 -> 54
C10: 2 | D10: 6 | K10: 32 | L10: =K10+L9 -> 184 | M10: 30 | N10: =M10+N9 -> 84
C11: 2 | D11: 7 | K11: 44 | L11: =K11+L10 -> 228 | M11: 22 | N11: =M11+N10 -> 106
C12: 2 | D12: 8 | K12: 28 | L12: =K12+L11 -> 256 | M12: 36 | N12: =M12+N11 -> 142
C13: 2 | D13: 9 | K13: 41 | L13: =K13+L12 -> 297 | M13: 53 | N13: =M13+N12 -> 195
C14: 3 | D14: 10 | K14: 40 | L14: =K14+L13 -> 337 | M14: 47 | N14: =M14+N13 -> 242
C15: 3 | D15: 11 | E15: 7 | F15: 7 | K15: 50 | L15: =K15+L14 -> 387 | M15: 77 | N15: =M15+N14 -> 319
C16: 3 | D16: 12 | E16: 34 | F16: 30 | K16: 50 | L16: =K16+L15 -> 437 | M16: 68 | N16: =M16+N15 -> 387
C17: 3 | D17: 13 | E17: 15 | F17: 9 | K17: 43 | L17: =K17+L16 -> 480 | M17: 72 | N17: =M17+N16 -> 459
C18: 4 | D18: 14 | E18: 26 | F18: 9 | K18: 37 | L18: =K18+L17 -> 517 | M18: 60 | N18: =M18+N17 -> 519
C19: 4 | D19: 15 | E19: 13 | F19: 7 | K19: 36 | L19: =K19+L18 -> 553 | M19: 62 | N19: =M19+N18 -> 581
C20: 4 | D20: 16 | E20: 12 | F20: 7 | K20: 48 | L20: =K20+L19 -> 601 | M20: 63 | N20: =M20+N19 -> 644
C21: 4 | D21: 17 | E21: 8 | F21: 8 | K21: 46 | L21: =K21+L20 -> 647 | M21: 65 | N21: =M21+N20 -> 709
C22: 4 | D22: 18 | E22: 12 | F22: 2 | K22: 14 | L22: =K22+L21 -> 661 | M22: 68 | N22: =M22+N21 -> 777
C23: 5 | D23: 19 | E23: 7 | F23: 6 | G23: =COUNTIFS('Automatisations métiers'!A:A,'2026'!C$3,'Automatisations métiers'!C:C,'2026'!D23) -> 3 | H23: =COUNTIFS('Automatisations Odoo'!A:A,'2026'!C$3,'Automatisations Odoo'!C:C,'2026'!D23) -> 0 | J23: =COUNTIFS('Maintenances Production'!A:A,'2026'!C$3,'Maintenances Production'!C:C,'2026'!D23) -> 1 | K23: 41 | L23: =K23+L22 -> 702 | M23: 73 | N23: =M23+N22 -> 850
C24: 5 | D24: 20 | E24: 11 | F24: 3 | G24: =COUNTIFS('Automatisations métiers'!A:A,'2026'!C$3,'Automatisations métiers'!C:C,'2026'!D24) -> 0 | H24: =COUNTIFS('Automatisations Odoo'!A:A,'2026'!C$3,'Automatisations Odoo'!C:C,'2026'!D24) -> 0 | J24: =COUNTIFS('Maintenances Production'!A:A,'2026'!C$3,'Maintenances Production'!C:C,'2026'!D24) -> 1 | K24: 32 | L24: =K24+L23 -> 734 | M24: 69 | N24: =M24+N23 -> 919
C25: 5 | D25: 21 | E25: 19 | F25: 0 | G25: =COUNTIFS('Automatisations métiers'!A:A,'2026'!C$3,'Automatisations métiers'!C:C,'2026'!D25) -> 0 | H25: =COUNTIFS('Automatisations Odoo'!A:A,'2026'!C$3,'Automatisations Odoo'!C:C,'2026'!D25) -> 0 | J25: =COUNTIFS('Maintenances Production'!A:A,'2026'!C$3,'Maintenances Production'!C:C,'2026'!D25) -> 0 | K25: 39 | L25: =K25+L24 -> 773 | M25: 63 | N25: =M25+N24 -> 982 | O25: Décision de prise en charge des attribution de ticket par Quentin
C26: 5 | D26: 22 | E26: 3 | F26: 3 | G26: =COUNTIFS('Automatisations métiers'!A:A,'2026'!C$3,'Automatisations métiers'!C:C,'2026'!D26) -> 2 | H26: =COUNTIFS('Automatisations Odoo'!A:A,'2026'!C$3,'Automatisations Odoo'!C:C,'2026'!D26) -> 1 | J26: =COUNTIFS('Maintenances Production'!A:A,'2026'!C$3,'Maintenances Production'!C:C,'2026'!D26) -> 0 | K26: 24 | L26: =K26+L25 -> 797 | M26: 72 | N26: =M26+N25 -> 1054 | O26: /
C27: 6 | D27: 23 | E27: 8 | F27: 0 | G27: =COUNTIFS('Automatisations métiers'!A:A,'2026'!C$3,'Automatisations métiers'!C:C,'2026'!D27) -> 1 | H27: =COUNTIFS('Automatisations Odoo'!A:A,'2026'!C$3,'Automatisations Odoo'!C:C,'2026'!D27) -> 1 | J27: =COUNTIFS('Maintenances Production'!A:A,'2026'!C$3,'Maintenances Production'!C:C,'2026'!D27) -> 0 | K27: 37 | L27: =K27+L26 -> 834 | M27: 77 | N27: =M27+N26 -> 1131 | O27: /
C28: 6 | D28: 24 | E28: 1 | F28: 3 | G28: =COUNTIFS('Automatisations métiers'!A:A,'2026'!C$3,'Automatisations métiers'!C:C,'2026'!D28) -> 1 | H28: =COUNTIFS('Automatisations Odoo'!A:A,'2026'!C$3,'Automatisations Odoo'!C:C,'2026'!D28) -> 1 | J28: =COUNTIFS('Maintenances Production'!A:A,'2026'!C$3,'Maintenances Production'!C:C,'2026'!D28) -> 0 | K28: 56 | L28: =K28+L27 -> 890 | M28: 104 | N28: =M28+N27 -> 1235 | O28: /
C29: 6 | D29: 25 | E29: 43 | F29: 16 | G29: =COUNTIFS('Automatisations métiers'!A:A,'2026'!C$3,'Automatisations métiers'!C:C,'2026'!D29) -> 0 | H29: =COUNTIFS('Automatisations Odoo'!A:A,'2026'!C$3,'Automatisations Odoo'!C:C,'2026'!D29) -> 0 | J29: =COUNTIFS('Maintenances Production'!A:A,'2026'!C$3,'Maintenances Production'!C:C,'2026'!D29) -> 0 | K29: 44 | L29: =K29+L28 -> 934 | M29: 78 | N29: =M29+N28 -> 1313 | O29: Absence du vendredi 12 juin de Quentin (infiltration) | P29: Mise en place d'un backup
C30: 6 | D30: 26 | E30: 24 | F30: 1 | G30: =COUNTIFS('Automatisations métiers'!A:A,'2026'!C$3,'Automatisations métiers'!C:C,'2026'!D30) -> 0 | H30: =COUNTIFS('Automatisations Odoo'!A:A,'2026'!C$3,'Automatisations Odoo'!C:C,'2026'!D30) -> 0 | J30: =COUNTIFS('Maintenances Production'!A:A,'2026'!C$3,'Maintenances Production'!C:C,'2026'!D30) -> 1 | K30: 37 | L30: =K30+L29 -> 971 | M30: 65 | N30: =M30+N29 -> 1378 | O30: /
C31: 7 | D31: 27 | E31: 21 | F31: 12 | G31: =COUNTIFS('Automatisations métiers'!A:A,'2026'!C$3,'Automatisations métiers'!C:C,'2026'!D31) -> 0 | H31: =COUNTIFS('Automatisations Odoo'!A:A,'2026'!C$3,'Automatisations Odoo'!C:C,'2026'!D31) -> 0 | J31: =COUNTIFS('Maintenances Production'!A:A,'2026'!C$3,'Maintenances Production'!C:C,'2026'!D31) -> 0 | K31: 38 | L31: =K31+L30 -> 1009 | M31: 53 | N31: =M31+N30 -> 1431 | O31: /
C32: 7 | D32: 28 | E32: 15 | F32: 2 | G32: =COUNTIFS('Automatisations métiers'!A:A,'2026'!C$3,'Automatisations métiers'!C:C,'2026'!D32) -> 1 | H32: =COUNTIFS('Automatisations Odoo'!A:A,'2026'!C$3,'Automatisations Odoo'!C:C,'2026'!D32) -> 0 | J32: =COUNTIFS('Maintenances Production'!A:A,'2026'!C$3,'Maintenances Production'!C:C,'2026'!D32) -> 0 | K32: 27 | L32: =K32+L31 -> 1036 | M32: 50 | N32: =M32+N31 -> 1481 | O32: Backup mis en place par Quentin avec Dominque + Préparation facilitation (email clair à IT@coverseal.com + hyperlink + procédure)
C33: 7 | D33: 29 | E33: 10 | F33: 0 | G33: =COUNTIFS('Automatisations métiers'!A:A,'2026'!C$3,'Automatisations métiers'!C:C,'2026'!D33) -> 1 | H33: =COUNTIFS('Automatisations Odoo'!A:A,'2026'!C$3,'Automatisations Odoo'!C:C,'2026'!D33) -> 0 | J33: =COUNTIFS('Maintenances Production'!A:A,'2026'!C$3,'Maintenances Production'!C:C,'2026'!D33) -> 0 | K33: 30 | L33: =K33+L32 -> 1066 | M33: 43 | N33: =M33+N32 -> 1524
C34: 7 | D34: 30 | E34: 0 | F34: 2 | G34: =COUNTIFS('Automatisations métiers'!A:A,'2026'!C$3,'Automatisations métiers'!C:C,'2026'!D34) -> 0 | H34: =COUNTIFS('Automatisations Odoo'!A:A,'2026'!C$3,'Automatisations Odoo'!C:C,'2026'!D34) -> 0 | J34: =COUNTIFS('Maintenances Production'!A:A,'2026'!C$3,'Maintenances Production'!C:C,'2026'!D34) -> 1 | K34: 9 | L34: =K34+L33 -> 1075 | M34: 45 | N34: =M34+N33 -> 1569 | O34: Gary n'étant pas présent, certaines taches demandées n'ont pas pu être faites (fiche de prod hors limites) | P34: Documentation + backup à mettre en place
C35: 7 | D35: 31 | E35: 7 | F35: 1 | G35: =COUNTIFS('Automatisations métiers'!A:A,'2026'!C$3,'Automatisations métiers'!C:C,'2026'!D35) -> 1 | H35: =COUNTIFS('Automatisations Odoo'!A:A,'2026'!C$3,'Automatisations Odoo'!C:C,'2026'!D35) -> 0 | I35: =SUMIFS('Tests Phishing'!F:F,'Tests Phishing'!A:A,'2026'!C$3,'Tests Phishing'!C:C,'2026'!D35) -> 0 | J35: =COUNTIFS('Maintenances Production'!A:A,'2026'!C$3,'Maintenances Production'!C:C,'2026'!D35) -> 0 | K35: 15 | L35: =K35+L34 -> 1090 | M35: 48 | N35: =M35+N34 -> 1617 | O35: Retour de l'équipe au complet, formation Bandi nous accaparant beaucoup de temps
C36: 8 | D36: 32 | G36: =COUNTIFS('Automatisations métiers'!A:A,'2026'!C$3,'Automatisations métiers'!C:C,'2026'!D36) -> 0 | H36: =COUNTIFS('Automatisations Odoo'!A:A,'2026'!C$3,'Automatisations Odoo'!C:C,'2026'!D36) -> 0 | I36: =SUMIFS('Tests Phishing'!F:F,'Tests Phishing'!A:A,'2026'!C$3,'Tests Phishing'!C:C,'2026'!D36) -> 0 | J36: =COUNTIFS('Maintenances Production'!A:A,'2026'!C$3,'Maintenances Production'!C:C,'2026'!D36) -> 0 | L36: =K36+L35 -> 1090 | N36: =M36+N35 -> 1617
C37: 8 | D37: 33 | G37: =COUNTIFS('Automatisations métiers'!A:A,'2026'!C$3,'Automatisations métiers'!C:C,'2026'!D37) -> 0 | H37: =COUNTIFS('Automatisations Odoo'!A:A,'2026'!C$3,'Automatisations Odoo'!C:C,'2026'!D37) -> 0 | I37: =SUMIFS('Tests Phishing'!F:F,'Tests Phishing'!A:A,'2026'!C$3,'Tests Phishing'!C:C,'2026'!D37) -> 0 | J37: =COUNTIFS('Maintenances Production'!A:A,'2026'!C$3,'Maintenances Production'!C:C,'2026'!D37) -> 0 | L37: =K37+L36 -> 1090 | N37: =M37+N36 -> 1617
C38: 8 | D38: 34 | G38: =COUNTIFS('Automatisations métiers'!A:A,'2026'!C$3,'Automatisations métiers'!C:C,'2026'!D38) -> 0 | H38: =COUNTIFS('Automatisations Odoo'!A:A,'2026'!C$3,'Automatisations Odoo'!C:C,'2026'!D38) -> 0 | I38: =SUMIFS('Tests Phishing'!F:F,'Tests Phishing'!A:A,'2026'!C$3,'Tests Phishing'!C:C,'2026'!D38) -> 0 | J38: =COUNTIFS('Maintenances Production'!A:A,'2026'!C$3,'Maintenances Production'!C:C,'2026'!D38) -> 0 | L38: =K38+L37 -> 1090 | N38: =M38+N37 -> 1617
C39: 8 | D39: 35 | G39: =COUNTIFS('Automatisations métiers'!A:A,'2026'!C$3,'Automatisations métiers'!C:C,'2026'!D39) -> 0 | H39: =COUNTIFS('Automatisations Odoo'!A:A,'2026'!C$3,'Automatisations Odoo'!C:C,'2026'!D39) -> 0 | I39: =SUMIFS('Tests Phishing'!F:F,'Tests Phishing'!A:A,'2026'!C$3,'Tests Phishing'!C:C,'2026'!D39) -> 0 | J39: =COUNTIFS('Maintenances Production'!A:A,'2026'!C$3,'Maintenances Production'!C:C,'2026'!D39) -> 0 | L39: =K39+L38 -> 1090 | N39: =M39+N38 -> 1617
C40: 9 | D40: 36 | G40: =COUNTIFS('Automatisations métiers'!A:A,'2026'!C$3,'Automatisations métiers'!C:C,'2026'!D40) -> 0 | H40: =COUNTIFS('Automatisations Odoo'!A:A,'2026'!C$3,'Automatisations Odoo'!C:C,'2026'!D40) -> 0 | I40: =SUMIFS('Tests Phishing'!F:F,'Tests Phishing'!A:A,'2026'!C$3,'Tests Phishing'!C:C,'2026'!D40) -> 0 | J40: =COUNTIFS('Maintenances Production'!A:A,'2026'!C$3,'Maintenances Production'!C:C,'2026'!D40) -> 0 | L40: =K40+L39 -> 1090 | N40: =M40+N39 -> 1617
C41: 9 | D41: 37 | G41: =COUNTIFS('Automatisations métiers'!A:A,'2026'!C$3,'Automatisations métiers'!C:C,'2026'!D41) -> 0 | H41: =COUNTIFS('Automatisations Odoo'!A:A,'2026'!C$3,'Automatisations Odoo'!C:C,'2026'!D41) -> 0 | I41: =SUMIFS('Tests Phishing'!F:F,'Tests Phishing'!A:A,'2026'!C$3,'Tests Phishing'!C:C,'2026'!D41) -> 0 | J41: =COUNTIFS('Maintenances Production'!A:A,'2026'!C$3,'Maintenances Production'!C:C,'2026'!D41) -> 0 | L41: =K41+L40 -> 1090 | N41: =M41+N40 -> 1617
...

Sheet Automatisations métiers
A1: Année | B1: Mois | C1: Semaine | D1: Expliquation | E1: Responsable
A2: 2026 | B2: 5 | C2: 19 | D2: FLUX B2C | E2: Gary
A3: 2026 | B3: 5 | C3: 19 | D3: N8N Mahieu | E3: Quentin
A4: 2026 | B4: 5 | C4: 19 | D4: N8N Odoo -> SMC | E4: Quentin
A5: 2026 | B5: 5 | C5: 22 | D5: BREG | E5: Quentin
A6: 2026 | B6: 5 | C6: 22 | D6: Rappel BREG | E6: Quentin
A7: 2026 | B7: 6 | C7: 23 | D7: Réception BREG -> Garantie Activée dans Elfsquad | E7: Quentin
A8: 2026 | B8: 6 | C8: 24 | D8: Mise à jour des fiches de production en V10 par Formulaire, en main par Ludo | E8: Quentin
A9: 2026 | B9: 7 | C9: 28 | D9: Flux B2B | E9: Gary
A10: 2026 | B10: 7 | C10: 29 | D10: Formulaire de création de nouveau poste pour les managers | E10: Loic
A11: 2026 | B11: 7 | C11: 31 | D11: Attribution des ventes aux bonnes personnes dans Odoo (Direct + REV - BE/FR) | E11: Gary

Sheet Automatisations Odoo
A1: Année | B1: Mois | C1: Semaine | D1: Expliquation | E1: Responsable
A2: 2026 | B2: 5 | C2: 22 | D2: Rapport Logistique | E2: Quentin
A3: 2026 | B3: 6 | C3: 23 | D3: Document BREG digital ajouté à la commande dans Odoo | E3: Quentin
A4: 2026 | B4: 6 | C4: 24 | D4: Mise à jour de Mailchimp quand modification CRM dans Odoo | E4: Quentin

Sheet Tests Phishing
A1: Année | B1: Mois | C1: Semaine | D1: Expliquation | E1: Responsable | F1: Nbr échecs
A2: 2026 | B2: 7 | C2: 31 | E2: Loic | F2: 0

Sheet Maintenances Production
A1: Année | B1: Mois | C1: Semaine | D1: Expliquation | E1: Responsable
A2: 2026 | B2: 5 | C2: 19 | D2: Redemarage de l'ensemble des Smartscans | E2: Loic
A3: 2026 | B3: 5 | C3: 20 | D3: Installation de Odoo sur l'ensemble des Smartscans + Check app Coverseal | E3: Loic
A4: 2026 | B4: 6 | C4: 26 | D4: Redemarage de l'ensemble des Smartscans | E4: Loic
A5: 2026 | B5: 7 | C5: 30 | D5: Redemarage de l'ensemble des Smartscans | E5: Loic

Sheet Nombre tickets par type
A1: Catégorie | B1: 2026-S31 | C1: 2026-S30 | D1: 2026-S29 | E1: 2026-S28 | F1: 2026-S27 | G1: 2026-S26 | H1: 2026-S25 | I1: 2026-S24 | J1: 2026-S23 | K1: 2026-S22 | L1: 2026-S21 | M1: 2026-S20 | N1: 2026-S19 | O1: 2026-S18 | P1: 2026-S17 | Q1: 2026-S16 | R1: 2026-S15 | S1: 2026-S14 | T1: 2026-S13 | U1: 2026-S12 | V1: 2026-S11 | W1: 2026-S10 | X1: 2026-S09 | Y1: 2026-S08 | Z1: 2026-S07 | AA1: 2026-S06 | AB1: 2026-S05 | AC1: 2026-S04 | AD1: 2026-S03 | AE1: 2026-S02 | AF1: Total 2026
A2: Automatisation | B2: 1 | C2: 0 | D2: 1 | E2: 1 | F2: 2 | G2: 1 | H2: 4 | I2: 2 | J2: 0 | K2: 0 | L2: 1 | M2: 0 | N2: 0 | O2: 0 | P2: 1 | Q2: 1 | R2: 4 | S2: 1 | T2: 0 | U2: 3 | V2: 1 | W2: 2 | X2: 4 | Y2: 3 | Z2: 0 | AA2: 2 | AB2: 0 | AC2: 0 | AD2: 2 | AE2: 0 | AF2: =SUM(B2:AE2) -> 37
A3: Becovis | B3: 0 | C3: 0 | D3: 0 | E3: 0 | F3: 0 | G3: 1 | H3: 0 | I3: 0 | J3: 0 | K3: 0 | L3: 0 | M3: 0 | N3: 0 | O3: 0 | P3: 0 | Q3: 0 | R3: 0 | S3: 0 | T3: 0 | U3: 0 | V3: 0 | W3: 0 | X3: 0 | Y3: 0 | Z3: 0 | AA3: 0 | AB3: 0 | AC3: 0 | AD3: 0 | AE3: 0 | AF3: =SUM(B3:AE3) -> 1
A4: Demande de matériel | B4: 0 | C4: 0 | D4: 0 | E4: 1 | F4: 0 | G4: 1 | H4: 2 | I4: 0 | J4: 0 | K4: 4 | L4: 3 | M4: 3 | N4: 1 | O4: 1 | P4: 3 | Q4: 3 | R4: 4 | S4: 1 | T4: 2 | U4: 4 | V4: 1 | W4: 1 | X4: 1 | Y4: 0 | Z4: 2 | AA4: 0 | AB4: 2 | AC4: 4 | AD4: 1 | AE4: 2 | AF4: =SUM(B4:AE4) -> 47
A5: Documentation à faire | B5: 0 | C5: 0 | D5: 0 | E5: 1 | F5: 2 | G5: 2 | H5: 1 | I5: 1 | J5: 2 | K5: 0 | L5: 0 | M5: 1 | N5: 2 | O5: 0 | P5: 0 | Q5: 0 | R5: 0 | S5: 0 | T5: 2 | U5: 3 | V5: 1 | W5: 1 | X5: 2 | Y5: 2 | Z5: 2 | AA5: 1 | AB5: 1 | AC5: 1 | AD5: 0 | AE5: 1 | AF5: =SUM(B5:AE5) -> 29
A6: Elfsquad | B6: 2 | C6: 2 | D6: 8 | E6: 5 | F6: 9 | G6: 10 | H6: 8 | I6: 14 | J6: 5 | K6: 6 | L6: 9 | M6: 10 | N6: 7 | O6: 4 | P6: 8 | Q6: 13 | R6: 9 | S6: 5 | T6: 12 | U6: 5 | V6: 12 | W6: 6 | X6: 7 | Y6: 4 | Z6: 6 | AA6: 4 | AB6: 4 | AC6: 2 | AD6: 6 | AE6: 7 | AF6: =SUM(B6:AE6) -> 209
A7: Exact | B7: 0 | C7: 0 | D7: 0 | E7: 0 | F7: 0 | G7: 0 | H7: 1 | I7: 1 | J7: 0 | K7: 1 | L7: 0 | M7: 0 | N7: 1 | O7: 0 | P7: 0 | Q7: 0 | R7: 0 | S7: 1 | T7: 1 | U7: 0 | V7: 0 | W7: 0 | X7: 0 | Y7: 0 | Z7: 0 | AA7: 0 | AB7: 0 | AC7: 0 | AD7: 0 | AE7: 0 | AF7: =SUM(B7:AE7) -> 6
A8: Extract | B8: 1 | C8: 0 | D8: 1 | E8: 0 | F8: 3 | G8: 0 | H8: 4 | I8: 4 | J8: 4 | K8: 2 | L8: 0 | M8: 1 | N8: 4 | O8: 1 | P8: 1 | Q8: 3 | R8: 2 | S8: 2 | T8: 0 | U8: 0 | V8: 1 | W8: 2 | X8: 1 | Y8: 3 | Z8: 4 | AA8: 2 | AB8: 3 | AC8: 1 | AD8: 4 | AE8: 1 | AF8: =SUM(B8:AE8) -> 55
A9: Google | B9: 0 | C9: 0 | D9: 0 | E9: 1 | F9: 1 | G9: 0 | H9: 0 | I9: 0 | J9: 0 | K9: 0 | L9: 1 | M9: 0 | N9: 0 | O9: 0 | P9: 0 | Q9: 0 | R9: 0 | S9: 1 | T9: 0 | U9: 0 | V9: 0 | W9: 0 | X9: 0 | Y9: 0 | Z9: 0 | AA9: 1 | AB9: 0 | AC9: 0 | AD9: 0 | AE9: 0 | AF9: =SUM(B9:AE9) -> 5
A10: Imprimante | B10: 0 | C10: 0 | D10: 0 | E10: 0 | F10: 3 | G10: 2 | H10: 0 | I10: 1 | J10: 2 | K10: 2 | L10: 0 | M10: 0 | N10: 1 | O10: 0 | P10: 2 | Q10: 1 | R10: 1 | S10: 1 | T10: 0 | U10: 1 | V10: 1 | W10: 0 | X10: 2 | Y10: 1 | Z10: 1 | AA10: 0 | AB10: 0 | AC10: 1 | AD10: 0 | AE10: 0 | AF10: =SUM(B10:AE10) -> 23
A11: Keeper | B11: 0 | C11: 0 | D11: 0 | E11: 0 | F11: 0 | G11: 0 | H11: 0 | I11: 0 | J11: 0 | K11: 0 | L11: 0 | M11: 0 | N11: 0 | O11: 0 | P11: 0 | Q11: 0 | R11: 1 | S11: 0 | T11: 0 | U11: 0 | V11: 0 | W11: 0 | X11: 0 | Y11: 0 | Z11: 0 | AA11: 0 | AB11: 0 | AC11: 1 | AD11: 0 | AE11: 1 | AF11: =SUM(B11:AE11) -> 3
A12: mini-ERP | B12: 0 | C12: 0 | D12: 0 | E12: 0 | F12: 1 | G12: 2 | H12: 5 | I12: 0 | J12: 0 | K12: 0 | L12: 2 | M12: 0 | N12: 0 | O12: 3 | P12: 4 | Q12: 7 | R12: 0 | S12: 4 | T12: 5 | U12: 10 | V12: 8 | W12: 7 | X12: 2 | Y12: 5 | Z12: 1 | AA12: 0 | AB12: 3 | AC12: 4 | AD12: 4 | AE12: 1 | AF12: =SUM(B12:AE12) -> 78
A13: NAS | B13: 0 | C13: 0 | D13: 2 | E13: 1 | F13: 0 | G13: 1 | H13: 0 | I13: 1 | J13: 2 | K13: 1 | L13: 1 | M13: 1 | N13: 0 | O13: 0 | P13: 0 | Q13: 0 | R13: 0 | S13: 0 | T13: 1 | U13: 1 | V13: 2 | W13: 1 | X13: 0 | Y13: 0 | Z13: 0 | AA13: 0 | AB13: 0 | AC13: 0 | AD13: 0 | AE13: 0 | AF13: =SUM(B13:AE13) -> 15
... A25: Website | B25: 0 | C25: 2 | D25: 0 | E25: 0 | F25: 0 | G25: 0 | H25: 0 | I25: 1 | J25: 0 | K25: 0 | L25: 0 | M25: 0 | N25: 0 | O25: 0 | P25: 0 | Q25: 0 | R25: 0 | S25: 1 | T25: 0 | U25: 0 | V25: 0 | W25: 0 | X25: 1 | Y25: 0 | Z25: 1 | AA25: 0 | AB25: 1 | AC25: 0 | AD25: 0 | AE25: 0 | AF25: =SUM(B25:AE25) -> 7
A26: Total hebdomadaire | B26: =SUM(B2:B25) -> 15 | C26: =SUM(C2:C25) -> 9 | D26: =SUM(D2:D25) -> 30 | E26: =SUM(E2:E25) -> 27 | F26: =SUM(F2:F25) -> 38 | G26: =SUM(G2:G25) -> 38 | H26: =SUM(H2:H25) -> 46 | I26: =SUM(I2:I25) -> 57 | ... AF26: =SUM(AF2:AF25) -> 1150

Sheet Nombre tickets par responsable
A1: Responsable | B1: 2026-S30 | C1: 2026-S29 | D1: 2026-S28 | E1: 2026-S27 | F1: 2026-S26 | G1: 2026-S25 | H1: 2026-S24 | I1: 2026-S23 | J1: 2026-S22 | K1: 2026-S21 | L1: 2026-S20 | M1: 2026-S19 | N1: 2026-S18 | O1: 2026-S17 | P1: 2026-S16 | Q1: 2026-S15 | R1: 2026-S14 | S1: 2026-S13 | T1: 2026-S12 | U1: 2026-S11 | V1: 2026-S10 | W1: 2026-S09 | X1: 2026-S08 | Y1: 2026-S07 | Z1: 2026-S06 | AA1: 2026-S05 | AB1: 2026-S04 | AC1: 2026-S03 | AD1: 2026-S02 | AE1: Total 2026
A2: Devits Quentin | B2: 7 | C2: 0 | D2: 2 | E2: 18 | F2: 21 | G2: 18 | H2: 34 | I2: 12 | J2: 7 | K2: 9 | L2: 9 | M2: 23 | N2: 3 | O2: 20 | P2: 22 | Q2: 8 | R2: 14 | S2: 5 | T2: 0 | U2: 0 | V2: 13 | W2: 16 | X2: 3 | Y2: 13 | Z2: 5 | AA2: 15 | AB2: 7 | AC2: 13 | AD2: 15 | AE2: =SUM(B2:AD2) -> 332
A3: Dominique Kudas | B3: 1 | C3: 4 | D3: 1 | E3: 5 | F3: 5 | G3: 5 | H3: 2 | I3: 1 | J3: 0 | K3: 0 | L3: 0 | M3: 0 | N3: 0 | O3: 0 | P3: 0 | Q3: 0 | R3: 0 | S3: 0 | T3: 0 | U3: 0 | V3: 0 | W3: 0 | X3: 0 | Y3: 0 | Z3: 0 | AA3: 0 | AB3: 0 | AC3: 0 | AD3: 0 | AE3: =SUM(B3:AD3) -> 24
A4: Gary Schreurs | B4: 1 | C4: 22 | D4: 15 | E4: 9 | F4: 5 | G4: 14 | H4: 9 | I4: 12 | J4: 9 | K4: 18 | L4: 15 | M4: 11 | N4: 8 | O4: 16 | P4: 21 | Q4: 14 | R4: 15 | S4: 25 | T4: 23 | U4: 26 | V4: 18 | W4: 13 | X4: 12 | Y4: 18 | Z4: 23 | AA4: 19 | AB4: 24 | AC4: 9 | AD4: 8 | AE4: =SUM(B4:AD4) -> 432
A5: Loic Voumard | B5: 0 | C5: 4 | D5: 9 | E5: 6 | F5: 6 | G5: 7 | H5: 11 | I5: 12 | J5: 8 | K5: 12 | L5: 8 | M5: 7 | N5: 3 | O5: 10 | P5: 5 | Q5: 14 | R5: 8 | S5: 13 | T5: 27 | U5: 24 | V5: 9 | W5: 12 | X5: 13 | Y5: 13 | Z5: 4 | AA5: 5 | AB5: 8 | AC5: 11 | AD5: 18 | AE5: =SUM(B5:AD5) -> 287
A6: Total hebdomadaire | B6: =SUM(B2:B5) -> 9 | C6: =SUM(C2:C5) -> 30 | D6: =SUM(D2:D5) -> 27 | E6: =SUM(E2:E5) -> 38 | F6: =SUM(F2:F5) -> 37 | G6: =SUM(G2:G5) -> 44 | H6: =SUM(H2:H5) -> 56 | I6: =SUM(I2:I5) -> 37 | ... AE6: =SUM(AE2:AE5) -> 1075
